C:\Users\tusha\Ecommerce_website\ShopBotAssistant\ShopBotAssistant> python populate_data.py
Starting database population...
Sample users created successfully!
Traceback (most recent call last):
  File "C:\Users\tusha\AppData\Local\Programs\Python\Python311\Lib\site-packages\sqlalchemy\engine\base.py", line 2116, in _exec_insertmany_context
    dialect.do_execute(
  File "C:\Users\tusha\AppData\Local\Programs\Python\Python311\Lib\site-packages\sqlalchemy\engine\default.py", line 924, in do_execute
    cursor.execute(statement, parameters)
sqlite3.OperationalError: table product has no column named brand

The above exception was the direct cause of the following exception:

Traceback (most recent call last):
  File "C:\Users\tusha\Ecommerce_website\ShopBotAssistant\ShopBotAssistant\populate_data.py", line 283, in <module>
    main()
  File "C:\Users\tusha\Ecommerce_website\ShopBotAssistant\ShopBotAssistant\populate_data.py", line 272, in main
    products_count = create_electronics_products()
                     ^^^^^^^^^^^^^^^^^^^^^^^^^^^^^
  File "C:\Users\tusha\Ecommerce_website\ShopBotAssistant\ShopBotAssistant\populate_data.py", line 200, in create_electronics_products
    db.session.commit()
  File "C:\Users\tusha\AppData\Local\Programs\Python\Python311\Lib\site-packages\sqlalchemy\orm\scoping.py", line 597, in commit
    return self._proxied.commit()
           ^^^^^^^^^^^^^^^^^^^^^^
  File "C:\Users\tusha\AppData\Local\Programs\Python\Python311\Lib\site-packages\sqlalchemy\orm\session.py", line 2017, in commit
    trans.commit(_to_root=True)
  File "<string>", line 2, in commit
  File "C:\Users\tusha\AppData\Local\Programs\Python\Python311\Lib\site-packages\sqlalchemy\orm\state_changes.py", line 139, in _go
    ret_value = fn(self, *arg, **kw)
                ^^^^^^^^^^^^^^^^^^^^
  File "C:\Users\tusha\AppData\Local\Programs\Python\Python311\Lib\site-packages\sqlalchemy\orm\session.py", line 1302, in commit
    self._prepare_impl()
  File "<string>", line 2, in _prepare_impl
  File "C:\Users\tusha\AppData\Local\Programs\Python\Python311\Lib\site-packages\sqlalchemy\orm\state_changes.py", line 139, in _go
    ret_value = fn(self, *arg, **kw)
                ^^^^^^^^^^^^^^^^^^^^
  File "C:\Users\tusha\AppData\Local\Programs\Python\Python311\Lib\site-packages\sqlalchemy\orm\session.py", line 1277, in _prepare_impl
    self.session.flush()
  File "C:\Users\tusha\AppData\Local\Programs\Python\Python311\Lib\site-packages\sqlalchemy\orm\session.py", line 4341, in flush
    self._flush(objects)
  File "C:\Users\tusha\AppData\Local\Programs\Python\Python311\Lib\site-packages\sqlalchemy\orm\session.py", line 4476, in _flush
    with util.safe_reraise():
  File "C:\Users\tusha\AppData\Local\Programs\Python\Python311\Lib\site-packages\sqlalchemy\util\langhelpers.py", line 146, in __exit__
    raise exc_value.with_traceback(exc_tb)
  File "C:\Users\tusha\AppData\Local\Programs\Python\Python311\Lib\site-packages\sqlalchemy\orm\session.py", line 4437, in _flush
    flush_context.execute()
  File "C:\Users\tusha\AppData\Local\Programs\Python\Python311\Lib\site-packages\sqlalchemy\orm\unitofwork.py", line 466, in execute
    rec.execute(self)
  File "C:\Users\tusha\AppData\Local\Programs\Python\Python311\Lib\site-packages\sqlalchemy\orm\unitofwork.py", line 642, in execute
    util.preloaded.orm_persistence.save_obj(
  File "C:\Users\tusha\AppData\Local\Programs\Python\Python311\Lib\site-packages\sqlalchemy\orm\persistence.py", line 93, in save_obj
    _emit_insert_statements(
  File "C:\Users\tusha\AppData\Local\Programs\Python\Python311\Lib\site-packages\sqlalchemy\orm\persistence.py", line 1143, in _emit_insert_statements
    result = connection.execute(
             ^^^^^^^^^^^^^^^^^^^
  File "C:\Users\tusha\AppData\Local\Programs\Python\Python311\Lib\site-packages\sqlalchemy\engine\base.py", line 1418, in execute
    return meth(
           ^^^^^
  File "C:\Users\tusha\AppData\Local\Programs\Python\Python311\Lib\site-packages\sqlalchemy\sql\elements.py", line 515, in _execute_on_connection
    return connection._execute_clauseelement(
           ^^^^^^^^^^^^^^^^^^^^^^^^^^^^^^^^^^
  File "C:\Users\tusha\AppData\Local\Programs\Python\Python311\Lib\site-packages\sqlalchemy\engine\base.py", line 1640, in _execute_clauseelement
    ret = self._execute_context(
          ^^^^^^^^^^^^^^^^^^^^^^
  File "C:\Users\tusha\AppData\Local\Programs\Python\Python311\Lib\site-packages\sqlalchemy\engine\base.py", line 1844, in _execute_context
    return self._exec_insertmany_context(dialect, context)
           ^^^^^^^^^^^^^^^^^^^^^^^^^^^^^^^^^^^^^^^^^^^^^^^
  File "C:\Users\tusha\AppData\Local\Programs\Python\Python311\Lib\site-packages\sqlalchemy\engine\base.py", line 2124, in _exec_insertmany_context
    self._handle_dbapi_exception(
  File "C:\Users\tusha\AppData\Local\Programs\Python\Python311\Lib\site-packages\sqlalchemy\engine\base.py", line 2353, in _handle_dbapi_exception
    raise sqlalchemy_exception.with_traceback(exc_info[2]) from e
  File "C:\Users\tusha\AppData\Local\Programs\Python\Python311\Lib\site-packages\sqlalchemy\engine\base.py", line 2116, in _exec_insertmany_context
    dialect.do_execute(
  File "C:\Users\tusha\AppData\Local\Programs\Python\Python311\Lib\site-packages\sqlalchemy\engine\default.py", line 924, in do_execute
    cursor.execute(statement, parameters)
sqlalchemy.exc.OperationalError: (sqlite3.OperationalError) table product has no column named brand
[SQL: INSERT INTO product (name, description, price, category, brand, sku, image_url, stock_quantity, in_stock, rating, reviews_count, weight, dimensions, specifications, created_at, updated_at) VALUES (?, ?, ?, ?, ?, ?, ?, ?, ?, ?, ?, ?, ?, ?, ?, ?) RETURNING id]
[parameters: ('Acer Pavilion 15', 'High-quality laptop from Acer. Processor: Apple M2 Ram: 64GB Storage: 2TB SSD Display: 14" Graphics: NVIDIA GTX 1650', 1164.87, 'Laptops', 'Acer', 'ACELAP1640', 'https://via.placeholder.com/300x300?text=Laptops', 63, 1, 3.9, 30, 2.39, '12x24x10cm', '{"processor": "Apple M2", "ram": "64GB", "storage": "2TB SSD", "display": "14\\"", "graphics": "NVIDIA GTX 1650"}', '2025-06-07 17:40:11.171799', '2025-06-07 17:40:11.171799')]
(Background on this error at: https://sqlalche.me/e/20/e3q8)
PS C:\Users\tusha\Ecommerce_website\ShopBotAssistant\ShopBotAssistant> python main.py
PS C:\Users\tusha\Ecommerce_website\ShopBotAssistant\ShopBotAssistant>