Windows PowerShell
Copyright (C) Microsoft Corporation. All rights reserved.

Install the latest PowerShell for new features and improvements! https://aka.ms/PSWindows

PS C:\Users\tusha\Ecommerce_website\ShopBotAssistant\ShopBotAssistant> python populate_data.py
Starting database population...
Sample users created successfully!
Traceback (most recent call last):
  File "C:\Users\tusha\AppData\Local\Programs\Python\Python311\Lib\site-packages\sqlalchemy\engine\base.py", line 2116, in _exec_insertmany_context
    dialect.do_execute(
  File "C:\Users\tusha\AppData\Local\Programs\Python\Python311\Lib\site-packages\sqlalchemy\engine\default.py", line 924, in do_execute
    cursor.execute(statement, parameters)
sqlite3.IntegrityError: UNIQUE constraint failed: product.sku

The above exception was the direct cause of the following exception:

Traceback (most recent call last):
  File "C:\Users\tusha\Ecommerce_website\ShopBotAssistant\ShopBotAssistant\populate_data.py", line 283, in <module>
    main()
  File "C:\Users\tusha\Ecommerce_website\ShopBotAssistant\ShopBotAssistant\populate_data.py", line 272, in main
    products_count = create_electronics_products()
                     ^^^^^^^^^^^^^^^^^^^^^^^^^^^^^
  File "C:\Users\tusha\Ecommerce_website\ShopBotAssistant\ShopBotAssistant\populate_data.py", line 200, in create_electronics_products
    db.session.commit()
  File "C:\Users\tusha\AppData\Local\Programs\Python\Python311\Lib\site-packages\sqlalchemy\orm\scoping.py", line 597, in commit
    return self._proxied.commit()
           ^^^^^^^^^^^^^^^^^^^^^^
  File "C:\Users\tusha\AppData\Local\Programs\Python\Python311\Lib\site-packages\sqlalchemy\orm\session.py", line 2017, in commit
    trans.commit(_to_root=True)
  File "<string>", line 2, in commit
  File "C:\Users\tusha\AppData\Local\Programs\Python\Python311\Lib\site-packages\sqlalchemy\orm\state_changes.py", line 139, in _go
    ret_value = fn(self, *arg, **kw)
                ^^^^^^^^^^^^^^^^^^^^
  File "C:\Users\tusha\AppData\Local\Programs\Python\Python311\Lib\site-packages\sqlalchemy\orm\session.py", line 1302, in commit
    self._prepare_impl()
  File "<string>", line 2, in _prepare_impl
  File "C:\Users\tusha\AppData\Local\Programs\Python\Python311\Lib\site-packages\sqlalchemy\orm\state_changes.py", line 139, in _go
    ret_value = fn(self, *arg, **kw)
                ^^^^^^^^^^^^^^^^^^^^
  File "C:\Users\tusha\AppData\Local\Programs\Python\Python311\Lib\site-packages\sqlalchemy\orm\session.py", line 1277, in _prepare_impl
    self.session.flush()
  File "C:\Users\tusha\AppData\Local\Programs\Python\Python311\Lib\site-packages\sqlalchemy\orm\session.py", line 4341, in flush
    self._flush(objects)
  File "C:\Users\tusha\AppData\Local\Programs\Python\Python311\Lib\site-packages\sqlalchemy\orm\session.py", line 4476, in _flush
    with util.safe_reraise():
  File "C:\Users\tusha\AppData\Local\Programs\Python\Python311\Lib\site-packages\sqlalchemy\util\langhelpers.py", line 146, in __exit__
    raise exc_value.with_traceback(exc_tb)
  File "C:\Users\tusha\AppData\Local\Programs\Python\Python311\Lib\site-packages\sqlalchemy\orm\session.py", line 4437, in _flush
    flush_context.execute()
  File "C:\Users\tusha\AppData\Local\Programs\Python\Python311\Lib\site-packages\sqlalchemy\orm\unitofwork.py", line 466, in execute
    rec.execute(self)
  File "C:\Users\tusha\AppData\Local\Programs\Python\Python311\Lib\site-packages\sqlalchemy\orm\unitofwork.py", line 642, in execute
    util.preloaded.orm_persistence.save_obj(
  File "C:\Users\tusha\AppData\Local\Programs\Python\Python311\Lib\site-packages\sqlalchemy\orm\persistence.py", line 93, in save_obj
    _emit_insert_statements(
  File "C:\Users\tusha\AppData\Local\Programs\Python\Python311\Lib\site-packages\sqlalchemy\orm\persistence.py", line 1143, in _emit_insert_statements
    result = connection.execute(
             ^^^^^^^^^^^^^^^^^^^
  File "C:\Users\tusha\AppData\Local\Programs\Python\Python311\Lib\site-packages\sqlalchemy\engine\base.py", line 1418, in execute
    return meth(
           ^^^^^
  File "C:\Users\tusha\AppData\Local\Programs\Python\Python311\Lib\site-packages\sqlalchemy\sql\elements.py", line 515, in _execute_on_connection
    return connection._execute_clauseelement(
           ^^^^^^^^^^^^^^^^^^^^^^^^^^^^^^^^^^
  File "C:\Users\tusha\AppData\Local\Programs\Python\Python311\Lib\site-packages\sqlalchemy\engine\base.py", line 1640, in _execute_clauseelement
    ret = self._execute_context(
          ^^^^^^^^^^^^^^^^^^^^^^
  File "C:\Users\tusha\AppData\Local\Programs\Python\Python311\Lib\site-packages\sqlalchemy\engine\base.py", line 1844, in _execute_context
    return self._exec_insertmany_context(dialect, context)
           ^^^^^^^^^^^^^^^^^^^^^^^^^^^^^^^^^^^^^^^^^^^^^^^
  File "C:\Users\tusha\AppData\Local\Programs\Python\Python311\Lib\site-packages\sqlalchemy\engine\base.py", line 2124, in _exec_insertmany_context
    self._handle_dbapi_exception(
  File "C:\Users\tusha\AppData\Local\Programs\Python\Python311\Lib\site-packages\sqlalchemy\engine\base.py", line 2353, in _handle_dbapi_exception
    raise sqlalchemy_exception.with_traceback(exc_info[2]) from e
  File "C:\Users\tusha\AppData\Local\Programs\Python\Python311\Lib\site-packages\sqlalchemy\engine\base.py", line 2116, in _exec_insertmany_context
    dialect.do_execute(
  File "C:\Users\tusha\AppData\Local\Programs\Python\Python311\Lib\site-packages\sqlalchemy\engine\default.py", line 924, in do_execute
    cursor.execute(statement, parameters)
sqlalchemy.exc.IntegrityError: (sqlite3.IntegrityError) UNIQUE constraint failed: product.sku
[SQL: INSERT INTO product (name, description, price, category, brand, sku, image_url, stock_quantity, in_stock, rating, reviews_count, weight, dimensions, specifications, created_at, updated_at) VALUES (?, ?, ?, ?, ?, ?, ?, ?, ?, ?, ?, ?, ?, ?, ?, ?) RETURNING id]
[parameters: ('Apple Tablet 817', 'High-quality tablet from Apple. Display: 12.9" Storage: 64GB Connectivity: Wi-Fi + Cellular', 932.91, 'Tablets', 'Apple', 'APPTAB8577', 'https://via.placeholder.com/300x300?text=Tablets', 4, 1, 4.6, 396, 2.54, '24x33x3cm', '{"display": "12.9\\"", "storage": "64GB", "connectivity": "Wi-Fi + Cellular"}', '2025-06-07 18:06:56.697900', '2025-06-07 18:06:56.697900')]
(Background on this error at: https://sqlalche.me/e/20/gkpj)
PS C:\Users\tusha\Ecommerce_website\ShopBotAssistant\ShopBotAssistant> python app.py
 * Serving Flask app 'app'
 * Debug mode: on
INFO:werkzeug:WARNING: This is a development server. Do not use it in a production deployment. Use a production WSGI server instead.
 * Running on all addresses (0.0.0.0)
 * Running on http://127.0.0.1:5000
 * Running on http://192.168.140.24:5000
INFO:werkzeug:Press CTRL+C to quit
INFO:werkzeug: * Restarting with watchdog (windowsapi)
WARNING:werkzeug: * Debugger is active!
INFO:werkzeug: * Debugger PIN: 899-271-941
INFO:werkzeug:192.168.140.24 - - [07/Jun/2025 23:37:54] "GET / HTTP/1.1" 302 -
INFO:werkzeug:192.168.140.24 - - [07/Jun/2025 23:37:54] "GET /login HTTP/1.1" 200 -
INFO:werkzeug: * Detected change in 'C:\\Users\\tusha\\AppData\\Local\\Programs\\Python\\Python311\\Lib\\site-packages\\flask_sqlalchemy\\session.py', reloading
INFO:werkzeug: * Detected change in 'C:\\Users\\tusha\\AppData\\Local\\Programs\\Python\\Python311\\Lib\\site-packages\\flask_sqlalchemy\\extension.py', reloading
INFO:werkzeug:192.168.140.24 - - [07/Jun/2025 23:38:03] "POST /login HTTP/1.1" 500 -
Traceback (most recent call last):
  File "C:\Users\tusha\AppData\Local\Programs\Python\Python311\Lib\site-packages\flask\app.py", line 1488, in __call__
    return self.wsgi_app(environ, start_response)
           ^^^^^^^^^^^^^^^^^^^^^^^^^^^^^^^^^^^^^^
  File "C:\Users\tusha\AppData\Local\Programs\Python\Python311\Lib\site-packages\werkzeug\middleware\proxy_fix.py", line 182, in __call__
    return self.app(environ, start_response)
           ^^^^^^^^^^^^^^^^^^^^^^^^^^^^^^^^^
  File "C:\Users\tusha\AppData\Local\Programs\Python\Python311\Lib\site-packages\flask\app.py", line 1466, in wsgi_app
    response = self.handle_exception(e)
               ^^^^^^^^^^^^^^^^^^^^^^^^
  File "C:\Users\tusha\AppData\Local\Programs\Python\Python311\Lib\site-packages\flask\app.py", line 1463, in wsgi_app
    response = self.full_dispatch_request()
               ^^^^^^^^^^^^^^^^^^^^^^^^^^^^
  File "C:\Users\tusha\AppData\Local\Programs\Python\Python311\Lib\site-packages\flask\app.py", line 872, in full_dispatch_request
    rv = self.handle_user_exception(e)
         ^^^^^^^^^^^^^^^^^^^^^^^^^^^^^
  File "C:\Users\tusha\AppData\Local\Programs\Python\Python311\Lib\site-packages\flask\app.py", line 870, in full_dispatch_request
    rv = self.dispatch_request()
         ^^^^^^^^^^^^^^^^^^^^^^^
  File "C:\Users\tusha\AppData\Local\Programs\Python\Python311\Lib\site-packages\flask\app.py", line 855, in dispatch_request
    return self.ensure_sync(self.view_functions[rule.endpoint])(**view_args)  # type: ignore[no-any-return]
           ^^^^^^^^^^^^^^^^^^^^^^^^^^^^^^^^^^^^^^^^^^^^^^^^^^^^^^^^^^^^^^^^^^^^^^^^^^^^^^^^^^^^^^^^^^^^^^^^
  File "C:\Users\tusha\Ecommerce_website\ShopBotAssistant\ShopBotAssistant\app.py", line 59, in login
    user = User.query.filter_by(email=email).first()
           ^^^^^^^^^^^^^^^^^^^^^^^^^^^^^^^^^^^^^^^^^
  File "C:\Users\tusha\AppData\Local\Programs\Python\Python311\Lib\site-packages\sqlalchemy\orm\query.py", line 2728, in first
    return self.limit(1)._iter().first()  # type: ignore
           ^^^^^^^^^^^^^^^^^^^^^^^^^^^^^^^^^^^^^^^^^^^^^
  File "C:\Users\tusha\AppData\Local\Programs\Python\Python311\Lib\site-packages\sqlalchemy\orm\query.py", line 2827, in _iter
    result: Union[ScalarResult[_T], Result[_T]] = self.session.execute(
                                                  ^^^^^^^^^^^^^^^^^^^^^
  File "C:\Users\tusha\AppData\Local\Programs\Python\Python311\Lib\site-packages\sqlalchemy\orm\session.py", line 2351, in execute
    return self._execute_internal(
           ^^^^^^^^^^^^^^^^^^^^^^^
  File "C:\Users\tusha\AppData\Local\Programs\Python\Python311\Lib\site-packages\sqlalchemy\orm\session.py", line 2224, in _execute_internal
    bind = self.get_bind(**bind_arguments)
           ^^^^^^^^^^^^^^^^^^^^^^^^^^^^^^^
  File "C:\Users\tusha\AppData\Local\Programs\Python\Python311\Lib\site-packages\flask_sqlalchemy\session.py", line 53, in get_bind
    engines = self._db.engines
              ^^^^^^^^^^^^^^^^
  File "C:\Users\tusha\AppData\Local\Programs\Python\Python311\Lib\site-packages\flask_sqlalchemy\extension.py", line 690, in engines
    raise RuntimeError(
RuntimeError: The current Flask app is not registered with this 'SQLAlchemy' instance. Did you forget to call 'init_app', or did you create multiple 'SQLAlchemy' instances?
INFO:werkzeug: * Restarting with watchdog (windowsapi)
WARNING:werkzeug: * Debugger is active!
INFO:werkzeug: * Debugger PIN: 899-271-941